Workbook

Sheet Dashboard
A1: E-commerce Order MIS Dashboard
A3: Q3 2026 (Jul - Sep) | Order, delivery and return performance
A6: TOTAL ORDERS | D6: GROSS REVENUE (INR) | G6: AVG ORDER VALUE (INR) | J6: DELIVERY RATE | M6: RETURN RATE | P6: RTO RATE
A7: ='Dashboard Data'!A5 -> 1200 | D7: ='Dashboard Data'!B5 -> 982716 | G7: ='Dashboard Data'!D5 -> 818.93 | J7: ='Dashboard Data'!A8 -> 0.82166667 | M7: ='Dashboard Data'!B8 -> 0.074166667 | P7: ='Dashboard Data'!D8 -> 0.064166667
A10: Daily Orders | J10: Revenue by Category (INR)
A30: Order Status Split | J30: Delivery % vs RTO % by Payment Mode

Sheet Dashboard Data
A1: E-commerce Order MIS Dashboard | Q3 2026 (Jul - Sep)
A2: Simulated D2C order data (1,200 orders). Every number below is a live formula on the Data sheet.
A4: Total Orders | B4: Gross Revenue (INR) | C4: Net Delivered Revenue (INR) | D4: Avg Order Value (INR) | E4: Avg Delivery Days
A5: =COUNTA(Data!$A$2:$A$1201) -> 1200 | B5: =SUM(Data!$H$2:$H$1201) -> 982716 | C5: =SUMIFS(Data!$H$2:$H$1201,Data!$J$2:$J$1201,"Delivered") -> 806446 | D5: =B5/A5 -> 818.93 | E5: =AVERAGE(Data!$K$2:$K$1201) -> 3.9823256
A7: Delivery Rate | B7: Return Rate | C7: Cancellation Rate | D7: RTO Rate | E7: COD Share
A8: =COUNTIFS(Data!$J$2:$J$1201,"Delivered")/A5 -> 0.82166667 | B8: =COUNTIFS(Data!$J$2:$J$1201,"Returned")/A5 -> 0.074166667 | C8: =COUNTIFS(Data!$J$2:$J$1201,"Cancelled")/A5 -> 0.04 | D8: =COUNTIFS(Data!$J$2:$J$1201,"RTO")/A5 -> 0.064166667 | E8: =COUNTIFS(Data!$I$2:$I$1201,"COD")/A5 -> 0.38583333
A11: Category Performance | F11: Payment Mode Analysis
A12: Category | B12: Orders | C12: Revenue (INR) | D12: Return % | F12: Payment Mode | G12: Orders | H12: Delivery % | I12: RTO %
A13: Skincare | B13: =COUNTIFS(Data!$D$2:$D$1201,A13) -> 367 | C13: =SUMIFS(Data!$H$2:$H$1201,Data!$D$2:$D$1201,A13) -> 310926 | D13: =IFERROR(COUNTIFS(Data!$D$2:$D$1201,A13,Data!$J$2:$J$1201,"Returned")/B13,0) -> 0.065395095 | F13: Prepaid | G13: =COUNTIFS(Data!$I$2:$I$1201,F13) -> 737 | H13: =IFERROR(COUNTIFS(Data!$I$2:$I$1201,F13,Data!$J$2:$J$1201,"Delivered")/G13,0) -> 0.88738128 | I13: =IFERROR(COUNTIFS(Data!$I$2:$I$1201,F13,Data!$J$2:$J$1201,"RTO")/G13,0) -> 0.0081411126
A14: Haircare | B14: =COUNTIFS(Data!$D$2:$D$1201,A14) -> 275 | C14: =SUMIFS(Data!$H$2:$H$1201,Data!$D$2:$D$1201,A14) -> 195228 | D14: =IFERROR(COUNTIFS(Data!$D$2:$D$1201,A14,Data!$J$2:$J$1201,"Returned")/B14,0) -> 0.08 | F14: COD | G14: =COUNTIFS(Data!$I$2:$I$1201,F14) -> 463 | H14: =IFERROR(COUNTIFS(Data!$I$2:$I$1201,F14,Data!$J$2:$J$1201,"Delivered")/G14,0) -> 0.71706263 | I14: =IFERROR(COUNTIFS(Data!$I$2:$I$1201,F14,Data!$J$2:$J$1201,"RTO")/G14,0) -> 0.15334773
A15: Bath & Body | B15: =COUNTIFS(Data!$D$2:$D$1201,A15) -> 203 | C15: =SUMIFS(Data!$H$2:$H$1201,Data!$D$2:$D$1201,A15) -> 130148 | D15: =IFERROR(COUNTIFS(Data!$D$2:$D$1201,A15,Data!$J$2:$J$1201,"Returned")/B15,0) -> 0.064039409
A16: Makeup | B16: =COUNTIFS(Data!$D$2:$D$1201,A16) -> 208 | C16: =SUMIFS(Data!$H$2:$H$1201,Data!$D$2:$D$1201,A16) -> 185124 | D16: =IFERROR(COUNTIFS(Data!$D$2:$D$1201,A16,Data!$J$2:$J$1201,"Returned")/B16,0) -> 0.091346154 | F16: Order Status Split
A17: Wellness | B17: =COUNTIFS(Data!$D$2:$D$1201,A17) -> 147 | C17: =SUMIFS(Data!$H$2:$H$1201,Data!$D$2:$D$1201,A17) -> 161290 | D17: =IFERROR(COUNTIFS(Data!$D$2:$D$1201,A17,Data!$J$2:$J$1201,"Returned")/B17,0) -> 0.074829932 | F17: Status | G17: Orders | H17: Share
F18: Delivered | G18: =COUNTIFS(Data!$J$2:$J$1201,F18) -> 986 | H18: =G18/$A$5 -> 0.82166667
F19: Returned | G19: =COUNTIFS(Data!$J$2:$J$1201,F19) -> 89 | H19: =G19/$A$5 -> 0.074166667
A20: City-wise Orders | F20: Cancelled | G20: =COUNTIFS(Data!$J$2:$J$1201,F20) -> 48 | H20: =G20/$A$5 -> 0.04
A21: City | B21: Orders | C21: Revenue (INR) | D21: Return % | F21: RTO | G21: =COUNTIFS(Data!$J$2:$J$1201,F21) -> 77 | H21: =G21/$A$5 -> 0.064166667
A22: Delhi | B22: =COUNTIFS(Data!$C$2:$C$1201,A22) -> 150 | C22: =SUMIFS(Data!$H$2:$H$1201,Data!$C$2:$C$1201,A22) -> 123640 | D22: =IFERROR(COUNTIFS(Data!$C$2:$C$1201,A22,Data!$J$2:$J$1201,"Returned")/B22,0) -> 0.02
A23: Mumbai | B23: =COUNTIFS(Data!$C$2:$C$1201,A23) -> 155 | C23: =SUMIFS(Data!$H$2:$H$1201,Data!$C$2:$C$1201,A23) -> 132832 | D23: =IFERROR(COUNTIFS(Data!$C$2:$C$1201,A23,Data!$J$2:$J$1201,"Returned")/B23,0) -> 0.064516129
A24: Bengaluru | B24: =COUNTIFS(Data!$C$2:$C$1201,A24) -> 156 | C24: =SUMIFS(Data!$H$2:$H$1201,Data!$C$2:$C$1201,A24) -> 129214 | D24: =IFERROR(COUNTIFS(Data!$C$2:$C$1201,A24,Data!$J$2:$J$1201,"Returned")/B24,0) -> 0.08974359
A25: Hyderabad | B25: =COUNTIFS(Data!$C$2:$C$1201,A25) -> 143 | C25: =SUMIFS(Data!$H$2:$H$1201,Data!$C$2:$C$1201,A25) -> 107488 | D25: =IFERROR(COUNTIFS(Data!$C$2:$C$1201,A25,Data!$J$2:$J$1201,"Returned")/B25,0) -> 0.11188811
A26: Pune | B26: =COUNTIFS(Data!$C$2:$C$1201,A26) -> 162 | C26: =SUMIFS(Data!$H$2:$H$1201,Data!$C$2:$C$1201,A26) -> 133180 | D26: =IFERROR(COUNTIFS(Data!$C$2:$C$1201,A26,Data!$J$2:$J$1201,"Returned")/B26,0) -> 0.086419753
A27: Kolkata | B27: =COUNTIFS(Data!$C$2:$C$1201,A27) -> 157 | C27: =SUMIFS(Data!$H$2:$H$1201,Data!$C$2:$C$1201,A27) -> 127796 | D27: =IFERROR(COUNTIFS(Data!$C$2:$C$1201,A27,Data!$J$2:$J$1201,"Returned")/B27,0) -> 0.057324841

Sheet Daily MIS
A1: Daily MIS Report
A2: All figures are formulas on the Data sheet (COUNTIFS / SUMIFS). Revenue = gross order value in INR.
A4: Date | B4: Orders | C4: Revenue (INR) | D4: Delivered | E4: Returned | F4: Cancelled | G4: RTO | H4: Delivery % | I4: Return % | J4: COD Orders
A5: 46204 | B5: =COUNTIFS(Data!$B$2:$B$1201,A5) -> 8 | C5: =SUMIFS(Data!$H$2:$H$1201,Data!$B$2:$B$1201,A5) -> 7590 | D5: =COUNTIFS(Data!$B$2:$B$1201,$A5,Data!$J$2:$J$1201,"Delivered") -> 7 | E5: =COUNTIFS(Data!$B$2:$B$1201,$A5,Data!$J$2:$J$1201,"Returned") -> 1 | F5: =COUNTIFS(Data!$B$2:$B$1201,$A5,Data!$J$2:$J$1201,"Cancelled") -> 0 | G5: =COUNTIFS(Data!$B$2:$B$1201,$A5,Data!$J$2:$J$1201,"RTO") -> 0 | H5: =IFERROR(D5/B5,0) -> 0.875 | I5: =IFERROR(E5/B5,0) -> 0.125 | J5: =COUNTIFS(Data!$B$2:$B$1201,$A5,Data!$I$2:$I$1201,"COD") -> 4
A6: 46205 | B6: =COUNTIFS(Data!$B$2:$B$1201,A6) -> 8 | C6: =SUMIFS(Data!$H$2:$H$1201,Data!$B$2:$B$1201,A6) -> 7576 | D6: =COUNTIFS(Data!$B$2:$B$1201,$A6,Data!$J$2:$J$1201,"Delivered") -> 5 | E6: =COUNTIFS(Data!$B$2:$B$1201,$A6,Data!$J$2:$J$1201,"Returned") -> 1 | F6: =COUNTIFS(Data!$B$2:$B$1201,$A6,Data!$J$2:$J$1201,"Cancelled") -> 1 | G6: =COUNTIFS(Data!$B$2:$B$1201,$A6,Data!$J$2:$J$1201,"RTO") -> 1 | H6: =IFERROR(D6/B6,0) -> 0.625 | I6: =IFERROR(E6/B6,0) -> 0.125 | J6: =COUNTIFS(Data!$B$2:$B$1201,$A6,Data!$I$2:$I$1201,"COD") -> 3
A7: 46206 | B7: =COUNTIFS(Data!$B$2:$B$1201,A7) -> 8 | C7: =SUMIFS(Data!$H$2:$H$1201,Data!$B$2:$B$1201,A7) -> 7178 | D7: =COUNTIFS(Data!$B$2:$B$1201,$A7,Data!$J$2:$J$1201,"Delivered") -> 6 | E7: =COUNTIFS(Data!$B$2:$B$1201,$A7,Data!$J$2:$J$1201,"Returned") -> 0 | F7: =COUNTIFS(Data!$B$2:$B$1201,$A7,Data!$J$2:$J$1201,"Cancelled") -> 0 | G7: =COUNTIFS(Data!$B$2:$B$1201,$A7,Data!$J$2:$J$1201,"RTO") -> 2 | H7: =IFERROR(D7/B7,0) -> 0.75 | I7: =IFERROR(E7/B7,0) -> 0 | J7: =COUNTIFS(Data!$B$2:$B$1201,$A7,Data!$I$2:$I$1201,"COD") -> 4
A8: 46207 | B8: =COUNTIFS(Data!$B$2:$B$1201,A8) -> 16 | C8: =SUMIFS(Data!$H$2:$H$1201,Data!$B$2:$B$1201,A8) -> 10942 | D8: =COUNTIFS(Data!$B$2:$B$1201,$A8,Data!$J$2:$J$1201,"Delivered") -> 14 | E8: =COUNTIFS(Data!$B$2:$B$1201,$A8,Data!$J$2:$J$1201,"Returned") -> 0 | F8: =COUNTIFS(Data!$B$2:$B$1201,$A8,Data!$J$2:$J$1201,"Cancelled") -> 0 | G8: =COUNTIFS(Data!$B$2:$B$1201,$A8,Data!$J$2:$J$1201,"RTO") -> 2 | H8: =IFERROR(D8/B8,0) -> 0.875 | I8: =IFERROR(E8/B8,0) -> 0 | J8: =COUNTIFS(Data!$B$2:$B$1201,$A8,Data!$I$2:$I$1201,"COD") -> 4
A9: 46208 | B9: =COUNTIFS(Data!$B$2:$B$1201,A9) -> 19 | C9: =SUMIFS(Data!$H$2:$H$1201,Data!$B$2:$B$1201,A9) -> 16470 | D9: =COUNTIFS(Data!$B$2:$B$1201,$A9,Data!$J$2:$J$1201,"Delivered") -> 17 | E9: =COUNTIFS(Data!$B$2:$B$1201,$A9,Data!$J$2:$J$1201,"Returned") -> 1 | F9: =COUNTIFS(Data!$B$2:$B$1201,$A9,Data!$J$2:$J$1201,"Cancelled") -> 0 | G9: =COUNTIFS(Data!$B$2:$B$1201,$A9,Data!$J$2:$J$1201,"RTO") -> 1 | H9: =IFERROR(D9/B9,0) -> 0.89473684 | I9: =IFERROR(E9/B9,0) -> 0.052631579 | J9: =COUNTIFS(Data!$B$2:$B$1201,$A9,Data!$I$2:$I$1201,"COD") -> 6
A10: 46209 | B10: =COUNTIFS(Data!$B$2:$B$1201,A10) -> 14 | C10: =SUMIFS(Data!$H$2:$H$1201,Data!$B$2:$B$1201,A10) -> 10822 | D10: =COUNTIFS(Data!$B$2:$B$1201,$A10,Data!$J$2:$J$1201,"Delivered") -> 13 | E10: =COUNTIFS(Data!$B$2:$B$1201,$A10,Data!$J$2:$J$1201,"Returned") -> 1 | F10: =COUNTIFS(Data!$B$2:$B$1201,$A10,Data!$J$2:$J$1201,"Cancelled") -> 0 | G10: =COUNTIFS(Data!$B$2:$B$1201,$A10,Data!$J$2:$J$1201,"RTO") -> 0 | H10: =IFERROR(D10/B10,0) -> 0.92857143 | I10: =IFERROR(E10/B10,0) -> 0.071428571 | J10: =COUNTIFS(Data!$B$2:$B$1201,$A10,Data!$I$2:$I$1201,"COD") -> 3
A11: 46210 | B11: =COUNTIFS(Data!$B$2:$B$1201,A11) -> 9 | C11: =SUMIFS(Data!$H$2:$H$1201,Data!$B$2:$B$1201,A11) -> 5742 | D11: =COUNTIFS(Data!$B$2:$B$1201,$A11,Data!$J$2:$J$1201,"Delivered") -> 8 | E11: =COUNTIFS(Data!$B$2:$B$1201,$A11,Data!$J$2:$J$1201,"Returned") -> 0 | F11: =COUNTIFS(Data!$B$2:$B$1201,$A11,Data!$J$2:$J$1201,"Cancelled") -> 0 | G11: =COUNTIFS(Data!$B$2:$B$1201,$A11,Data!$J$2:$J$1201,"RTO") -> 1 | H11: =IFERROR(D11/B11,0) -> 0.88888889 | I11: =IFERROR(E11/B11,0) -> 0 | J11: =COUNTIFS(Data!$B$2:$B$1201,$A11,Data!$I$2:$I$1201,"COD") -> 7
A12: 46211 | B12: =COUNTIFS(Data!$B$2:$B$1201,A12) -> 8 | C12: =SUMIFS(Data!$H$2:$H$1201,Data!$B$2:$B$1201,A12) -> 5912 | D12: =COUNTIFS(Data!$B$2:$B$1201,$A12,Data!$J$2:$J$1201,"Delivered") -> 7 | E12: =COUNTIFS(Data!$B$2:$B$1201,$A12,Data!$J$2:$J$1201,"Returned") -> 1 | F12: =COUNTIFS(Data!$B$2:$B$1201,$A12,Data!$J$2:$J$1201,"Cancelled") -> 0 | G12: =COUNTIFS(Data!$B$2:$B$1201,$A12,Data!$J$2:$J$1201,"RTO") -> 0 | H12: =IFERROR(D12/B12,0) -> 0.875 | I12: =IFERROR(E12/B12,0) -> 0.125 | J12: =COUNTIFS(Data!$B$2:$B$1201,$A12,Data!$I$2:$I$1201,"COD") -> 2
A13: 46212 | B13: =COUNTIFS(Data!$B$2:$B$1201,A13) -> 6 | C13: =SUMIFS(Data!$H$2:$H$1201,Data!$B$2:$B$1201,A13) -> 5102 | D13: =COUNTIFS(Data!$B$2:$B$1201,$A13,Data!$J$2:$J$1201,"Delivered") -> 5 | E13: =COUNTIFS(Data!$B$2:$B$1201,$A13,Data!$J$2:$J$1201,"Returned") -> 1 | F13: =COUNTIFS(Data!$B$2:$B$1201,$A13,Data!$J$2:$J$1201,"Cancelled") -> 0 | G13: =COUNTIFS(Data!$B$2:$B$1201,$A13,Data!$J$2:$J$1201,"RTO") -> 0 | H13: =IFERROR(D13/B13,0) -> 0.83333333 | I13: =IFERROR(E13/B13,0) -> 0.16666667 | J13: =COUNTIFS(Data!$B$2:$B$1201,$A13,Data!$I$2:$I$1201,"COD") -> 3
A14: 46213 | B14: =COUNTIFS(Data!$B$2:$B$1201,A14) -> 12 | C14: =SUMIFS(Data!$H$2:$H$1201,Data!$B$2:$B$1201,A14) -> 9218 | D14: =COUNTIFS(Data!$B$2:$B$1201,$A14,Data!$J$2:$J$1201,"Delivered") -> 12 | E14: =COUNTIFS(Data!$B$2:$B$1201,$A14,Data!$J$2:$J$1201,"Returned") -> 0 | F14: =COUNTIFS(Data!$B$2:$B$1201,$A14,Data!$J$2:$J$1201,"Cancelled") -> 0 | G14: =COUNTIFS(Data!$B$2:$B$1201,$A14,Data!$J$2:$J$1201,"RTO") -> 0 | H14: =IFERROR(D14/B14,0) -> 1 | I14: =IFERROR(E14/B14,0) -> 0 | J14: =COUNTIFS(Data!$B$2:$B$1201,$A14,Data!$I$2:$I$1201,"COD") -> 4
A15: 46214 | B15: =COUNTIFS(Data!$B$2:$B$1201,A15) -> 16 | C15: =SUMIFS(Data!$H$2:$H$1201,Data!$B$2:$B$1201,A15) -> 12718 | D15: =COUNTIFS(Data!$B$2:$B$1201,$A15,Data!$J$2:$J$1201,"Delivered") -> 13 | E15: =COUNTIFS(Data!$B$2:$B$1201,$A15,Data!$J$2:$J$1201,"Returned") -> 2 | F15: =COUNTIFS(Data!$B$2:$B$1201,$A15,Data!$J$2:$J$1201,"Cancelled") -> 1 | G15: =COUNTIFS(Data!$B$2:$B$1201,$A15,Data!$J$2:$J$1201,"RTO") -> 0 | H15: =IFERROR(D15/B15,0) -> 0.8125 | I15: =IFERROR(E15/B15,0) -> 0.125 | J15: =COUNTIFS(Data!$B$2:$B$1201,$A15,Data!$I$2:$I$1201,"COD") -> 5
A16: 46215 | B16: =COUNTIFS(Data!$B$2:$B$1201,A16) -> 19 | C16: =SUMIFS(Data!$H$2:$H$1201,Data!$B$2:$B$1201,A16) -> 13882 | D16: =COUNTIFS(Data!$B$2:$B$1201,$A16,Data!$J$2:$J$1201,"Delivered") -> 16 | E16: =COUNTIFS(Data!$B$2:$B$1201,$A16,Data!$J$2:$J$1201,"Returned") -> 2 | F16: =COUNTIFS(Data!$B$2:$B$1201,$A16,Data!$J$2:$J$1201,"Cancelled") -> 0 | G16: =COUNTIFS(Data!$B$2:$B$1201,$A16,Data!$J$2:$J$1201,"RTO") -> 1 | H16: =IFERROR(D16/B16,0) -> 0.84210526 | I16: =IFERROR(E16/B16,0) -> 0.10526316 | J16: =COUNTIFS(Data!$B$2:$B$1201,$A16,Data!$I$2:$I$1201,"COD") -> 7
... A96: 46295 | B96: =COUNTIFS(Data!$B$2:$B$1201,A96) -> 9 | C96: =SUMIFS(Data!$H$2:$H$1201,Data!$B$2:$B$1201,A96) -> 6428 | D96: =COUNTIFS(Data!$B$2:$B$1201,$A96,Data!$J$2:$J$1201,"Delivered") -> 7 | E96: =COUNTIFS(Data!$B$2:$B$1201,$A96,Data!$J$2:$J$1201,"Returned") -> 1 | F96: =COUNTIFS(Data!$B$2:$B$1201,$A96,Data!$J$2:$J$1201,"Cancelled") -> 1 | G96: =COUNTIFS(Data!$B$2:$B$1201,$A96,Data!$J$2:$J$1201,"RTO") -> 0 | H96: =IFERROR(D96/B96,0) -> 0.77777778 | I96: =IFERROR(E96/B96,0) -> 0.11111111 | J96: =COUNTIFS(Data!$B$2:$B$1201,$A96,Data!$I$2:$I$1201,"COD") -> 4
A97: Total | B97: =SUM(B5:B96) -> 1200 | C97: =SUM(C5:C96) -> 982716 | D97: =SUM(D5:D96) -> 986 | E97: =SUM(E5:E96) -> 89 | F97: =SUM(F5:F96) -> 48 | G97: =SUM(G5:G96) -> 77 | H97: =IFERROR(D97/B97,0) -> 0.82166667 | I97: =IFERROR(E97/B97,0) -> 0.074166667 | J97: =SUM(J5:J96) -> 463

Sheet Weekly MIS
A1: Weekly MIS Report
A3: Week | B3: Week Start | C3: Week End | D3: Orders | E3: Revenue (INR) | F3: Delivered | G3: Returned | H3: Cancelled | I3: RTO | J3: Delivery % | K3: Return %
A4: Week 1 | B4: 46204 | C4: =B4+6 -> 46210 | D4: =COUNTIFS(Data!$B$2:$B$1201,">="&$B4,Data!$B$2:$B$1201,"<="&$C4) -> 82 | E4: =SUMIFS(Data!$H$2:$H$1201,Data!$B$2:$B$1201,">="&$B4,Data!$B$2:$B$1201,"<="&$C4) -> 66320 | F4: =COUNTIFS(Data!$B$2:$B$1201,">="&$B4,Data!$B$2:$B$1201,"<="&$C4,Data!$J$2:$J$1201,"Delivered") -> 70 | G4: =COUNTIFS(Data!$B$2:$B$1201,">="&$B4,Data!$B$2:$B$1201,"<="&$C4,Data!$J$2:$J$1201,"Returned") -> 4 | H4: =COUNTIFS(Data!$B$2:$B$1201,">="&$B4,Data!$B$2:$B$1201,"<="&$C4,Data!$J$2:$J$1201,"Cancelled") -> 1 | I4: =COUNTIFS(Data!$B$2:$B$1201,">="&$B4,Data!$B$2:$B$1201,"<="&$C4,Data!$J$2:$J$1201,"RTO") -> 7 | J4: =IFERROR(F4/D4,0) -> 0.85365854 | K4: =IFERROR(G4/D4,0) -> 0.048780488
A5: Week 2 | B5: 46211 | C5: =B5+6 -> 46217 | D5: =COUNTIFS(Data!$B$2:$B$1201,">="&$B5,Data!$B$2:$B$1201,"<="&$C5) -> 77 | E5: =SUMIFS(Data!$H$2:$H$1201,Data!$B$2:$B$1201,">="&$B5,Data!$B$2:$B$1201,"<="&$C5) -> 60666 | F5: =COUNTIFS(Data!$B$2:$B$1201,">="&$B5,Data!$B$2:$B$1201,"<="&$C5,Data!$J$2:$J$1201,"Delivered") -> 68 | G5: =COUNTIFS(Data!$B$2:$B$1201,">="&$B5,Data!$B$2:$B$1201,"<="&$C5,Data!$J$2:$J$1201,"Returned") -> 7 | H5: =COUNTIFS(Data!$B$2:$B$1201,">="&$B5,Data!$B$2:$B$1201,"<="&$C5,Data!$J$2:$J$1201,"Cancelled") -> 1 | I5: =COUNTIFS(Data!$B$2:$B$1201,">="&$B5,Data!$B$2:$B$1201,"<="&$C5,Data!$J$2:$J$1201,"RTO") -> 1 | J5: =IFERROR(F5/D5,0) -> 0.88311688 | K5: =IFERROR(G5/D5,0) -> 0.090909091
A6: Week 3 | B6: 46218 | C6: =B6+6 -> 46224 | D6: =COUNTIFS(Data!$B$2:$B$1201,">="&$B6,Data!$B$2:$B$1201,"<="&$C6) -> 88 | E6: =SUMIFS(Data!$H$2:$H$1201,Data!$B$2:$B$1201,">="&$B6,Data!$B$2:$B$1201,"<="&$C6) -> 72412 | F6: =COUNTIFS(Data!$B$2:$B$1201,">="&$B6,Data!$B$2:$B$1201,"<="&$C6,Data!$J$2:$J$1201,"Delivered") -> 68 | G6: =COUNTIFS(Data!$B$2:$B$1201,">="&$B6,Data!$B$2:$B$1201,"<="&$C6,Data!$J$2:$J$1201,"Returned") -> 8 | H6: =COUNTIFS(Data!$B$2:$B$1201,">="&$B6,Data!$B$2:$B$1201,"<="&$C6,Data!$J$2:$J$1201,"Cancelled") -> 4 | I6: =COUNTIFS(Data!$B$2:$B$1201,">="&$B6,Data!$B$2:$B$1201,"<="&$C6,Data!$J$2:$J$1201,"RTO") -> 8 | J6: =IFERROR(F6/D6,0) -> 0.77272727 | K6: =IFERROR(G6/D6,0) -> 0.090909091
A7: Week 4 | B7: 46225 | C7: =B7+6 -> 46231 | D7: =COUNTIFS(Data!$B$2:$B$1201,">="&$B7,Data!$B$2:$B$1201,"<="&$C7) -> 89 | E7: =SUMIFS(Data!$H$2:$H$1201,Data!$B$2:$B$1201,">="&$B7,Data!$B$2:$B$1201,"<="&$C7) -> 70366 | F7: =COUNTIFS(Data!$B$2:$B$1201,">="&$B7,Data!$B$2:$B$1201,"<="&$C7,Data!$J$2:$J$1201,"Delivered") -> 74 | G7: =COUNTIFS(Data!$B$2:$B$1201,">="&$B7,Data!$B$2:$B$1201,"<="&$C7,Data!$J$2:$J$1201,"Returned") -> 4 | H7: =COUNTIFS(Data!$B$2:$B$1201,">="&$B7,Data!$B$2:$B$1201,"<="&$C7,Data!$J$2:$J$1201,"Cancelled") -> 4 | I7: =COUNTIFS(Data!$B$2:$B$1201,">="&$B7,Data!$B$2:$B$1201,"<="&$C7,Data!$J$2:$J$1201,"RTO") -> 7 | J7: =IFERROR(F7/D7,0) -> 0.83146067 | K7: =IFERROR(G7/D7,0) -> 0.04494382
A8: Week 5 | B8: 46232 | C8: =B8+6 -> 46238 | D8: =COUNTIFS(Data!$B$2:$B$1201,">="&$B8,Data!$B$2:$B$1201,"<="&$C8) -> 84 | E8: =SUMIFS(Data!$H$2:$H$1201,Data!$B$2:$B$1201,">="&$B8,Data!$B$2:$B$1201,"<="&$C8) -> 69020 | F8: =COUNTIFS(Data!$B$2:$B$1201,">="&$B8,Data!$B$2:$B$1201,"<="&$C8,Data!$J$2:$J$1201,"Delivered") -> 71 | G8: =COUNTIFS(Data!$B$2:$B$1201,">="&$B8,Data!$B$2:$B$1201,"<="&$C8,Data!$J$2:$J$1201,"Returned") -> 8 | H8: =COUNTIFS(Data!$B$2:$B$1201,">="&$B8,Data!$B$2:$B$1201,"<="&$C8,Data!$J$2:$J$1201,"Cancelled") -> 3 | I8: =COUNTIFS(Data!$B$2:$B$1201,">="&$B8,Data!$B$2:$B$1201,"<="&$C8,Data!$J$2:$J$1201,"RTO") -> 2 | J8: =IFERROR(F8/D8,0) -> 0.8452381 | K8: =IFERROR(G8/D8,0) -> 0.095238095
A9: Week 6 | B9: 46239 | C9: =B9+6 -> 46245 | D9: =COUNTIFS(Data!$B$2:$B$1201,">="&$B9,Data!$B$2:$B$1201,"<="&$C9) -> 94 | E9: =SUMIFS(Data!$H$2:$H$1201,Data!$B$2:$B$1201,">="&$B9,Data!$B$2:$B$1201,"<="&$C9) -> 75728 | F9: =COUNTIFS(Data!$B$2:$B$1201,">="&$B9,Data!$B$2:$B$1201,"<="&$C9,Data!$J$2:$J$1201,"Delivered") -> 74 | G9: =COUNTIFS(Data!$B$2:$B$1201,">="&$B9,Data!$B$2:$B$1201,"<="&$C9,Data!$J$2:$J$1201,"Returned") -> 9 | H9: =COUNTIFS(Data!$B$2:$B$1201,">="&$B9,Data!$B$2:$B$1201,"<="&$C9,Data!$J$2:$J$1201,"Cancelled") -> 4 | I9: =COUNTIFS(Data!$B$2:$B$1201,">="&$B9,Data!$B$2:$B$1201,"<="&$C9,Data!$J$2:$J$1201,"RTO") -> 7 | J9: =IFERROR(F9/D9,0) -> 0.78723404 | K9: =IFERROR(G9/D9,0) -> 0.095744681
A10: Week 7 | B10: 46246 | C10: =B10+6 -> 46252 | D10: =COUNTIFS(Data!$B$2:$B$1201,">="&$B10,Data!$B$2:$B$1201,"<="&$C10) -> 91 | E10: =SUMIFS(Data!$H$2:$H$1201,Data!$B$2:$B$1201,">="&$B10,Data!$B$2:$B$1201,"<="&$C10) -> 77860 | F10: =COUNTIFS(Data!$B$2:$B$1201,">="&$B10,Data!$B$2:$B$1201,"<="&$C10,Data!$J$2:$J$1201,"Delivered") -> 71 | G10: =COUNTIFS(Data!$B$2:$B$1201,">="&$B10,Data!$B$2:$B$1201,"<="&$C10,Data!$J$2:$J$1201,"Returned") -> 10 | H10: =COUNTIFS(Data!$B$2:$B$1201,">="&$B10,Data!$B$2:$B$1201,"<="&$C10,Data!$J$2:$J$1201,"Cancelled") -> 3 | I10: =COUNTIFS(Data!$B$2:$B$1201,">="&$B10,Data!$B$2:$B$1201,"<="&$C10,Data!$J$2:$J$1201,"RTO") -> 7 | J10: =IFERROR(F10/D10,0) -> 0.78021978 | K10: =IFERROR(G10/D10,0) -> 0.10989011
A11: Week 8 | B11: 46253 | C11: =B11+6 -> 46259 | D11: =COUNTIFS(Data!$B$2:$B$1201,">="&$B11,Data!$B$2:$B$1201,"<="&$C11) -> 91 | E11: =SUMIFS(Data!$H$2:$H$1201,Data!$B$2:$B$1201,">="&$B11,Data!$B$2:$B$1201,"<="&$C11) -> 71172 | F11: =COUNTIFS(Data!$B$2:$B$1201,">="&$B11,Data!$B$2:$B$1201,"<="&$C11,Data!$J$2:$J$1201,"Delivered") -> 80 | G11: =COUNTIFS(Data!$B$2:$B$1201,">="&$B11,Data!$B$2:$B$1201,"<="&$C11,Data!$J$2:$J$1201,"Returned") -> 3 | H11: =COUNTIFS(Data!$B$2:$B$1201,">="&$B11,Data!$B$2:$B$1201,"<="&$C11,Data!$J$2:$J$1201,"Cancelled") -> 3 | I11: =COUNTIFS(Data!$B$2:$B$1201,">="&$B11,Data!$B$2:$B$1201,"<="&$C11,Data!$J$2:$J$1201,"RTO") -> 5 | J11: =IFERROR(F11/D11,0) -> 0.87912088 | K11: =IFERROR(G11/D11,0) -> 0.032967033
A12: Week 9 | B12: 46260 | C12: =B12+6 -> 46266 | D12: =COUNTIFS(Data!$B$2:$B$1201,">="&$B12,Data!$B$2:$B$1201,"<="&$C12) -> 103 | E12: =SUMIFS(Data!$H$2:$H$1201,Data!$B$2:$B$1201,">="&$B12,Data!$B$2:$B$1201,"<="&$C12) -> 85432 | F12: =COUNTIFS(Data!$B$2:$B$1201,">="&$B12,Data!$B$2:$B$1201,"<="&$C12,Data!$J$2:$J$1201,"Delivered") -> 86 | G12: =COUNTIFS(Data!$B$2:$B$1201,">="&$B12,Data!$B$2:$B$1201,"<="&$C12,Data!$J$2:$J$1201,"Returned") -> 2 | H12: =COUNTIFS(Data!$B$2:$B$1201,">="&$B12,Data!$B$2:$B$1201,"<="&$C12,Data!$J$2:$J$1201,"Cancelled") -> 5 | I12: =COUNTIFS(Data!$B$2:$B$1201,">="&$B12,Data!$B$2:$B$1201,"<="&$C12,Data!$J$2:$J$1201,"RTO") -> 10 | J12: =IFERROR(F12/D12,0) -> 0.83495146 | K12: =IFERROR(G12/D12,0) -> 0.019417476
A13: Week 10 | B13: 46267 | C13: =B13+6 -> 46273 | D13: =COUNTIFS(Data!$B$2:$B$1201,">="&$B13,Data!$B$2:$B$1201,"<="&$C13) -> 91 | E13: =SUMIFS(Data!$H$2:$H$1201,Data!$B$2:$B$1201,">="&$B13,Data!$B$2:$B$1201,"<="&$C13) -> 77542 | F13: =COUNTIFS(Data!$B$2:$B$1201,">="&$B13,Data!$B$2:$B$1201,"<="&$C13,Data!$J$2:$J$1201,"Delivered") -> 74 | G13: =COUNTIFS(Data!$B$2:$B$1201,">="&$B13,Data!$B$2:$B$1201,"<="&$C13,Data!$J$2:$J$1201,"Returned") -> 5 | H13: =COUNTIFS(Data!$B$2:$B$1201,">="&$B13,Data!$B$2:$B$1201,"<="&$C13,Data!$J$2:$J$1201,"Cancelled") -> 4 | I13: =COUNTIFS(Data!$B$2:$B$1201,">="&$B13,Data!$B$2:$B$1201,"<="&$C13,Data!$J$2:$J$1201,"RTO") -> 8 | J13: =IFERROR(F13/D13,0) -> 0.81318681 | K13: =IFERROR(G13/D13,0) -> 0.054945055
A14: Week 11 | B14: 46274 | C14: =B14+6 -> 46280 | D14: =COUNTIFS(Data!$B$2:$B$1201,">="&$B14,Data!$B$2:$B$1201,"<="&$C14) -> 95 | E14: =SUMIFS(Data!$H$2:$H$1201,Data!$B$2:$B$1201,">="&$B14,Data!$B$2:$B$1201,"<="&$C14) -> 76028 | F14: =COUNTIFS(Data!$B$2:$B$1201,">="&$B14,Data!$B$2:$B$1201,"<="&$C14,Data!$J$2:$J$1201,"Delivered") -> 80 | G14: =COUNTIFS(Data!$B$2:$B$1201,">="&$B14,Data!$B$2:$B$1201,"<="&$C14,Data!$J$2:$J$1201,"Returned") -> 5 | H14: =COUNTIFS(Data!$B$2:$B$1201,">="&$B14,Data!$B$2:$B$1201,"<="&$C14,Data!$J$2:$J$1201,"Cancelled") -> 2 | I14: =COUNTIFS(Data!$B$2:$B$1201,">="&$B14,Data!$B$2:$B$1201,"<="&$C14,Data!$J$2:$J$1201,"RTO") -> 8 | J14: =IFERROR(F14/D14,0) -> 0.84210526 | K14: =IFERROR(G14/D14,0) -> 0.052631579
A15: Week 12 | B15: 46281 | C15: =B15+6 -> 46287 | D15: =COUNTIFS(Data!$B$2:$B$1201,">="&$B15,Data!$B$2:$B$1201,"<="&$C15) -> 96 | E15: =SUMIFS(Data!$H$2:$H$1201,Data!$B$2:$B$1201,">="&$B15,Data!$B$2:$B$1201,"<="&$C15) -> 77148 | F15: =COUNTIFS(Data!$B$2:$B$1201,">="&$B15,Data!$B$2:$B$1201,"<="&$C15,Data!$J$2:$J$1201,"Delivered") -> 71 | G15: =COUNTIFS(Data!$B$2:$B$1201,">="&$B15,Data!$B$2:$B$1201,"<="&$C15,Data!$J$2:$J$1201,"Returned") -> 15 | H15: =COUNTIFS(Data!$B$2:$B$1201,">="&$B15,Data!$B$2:$B$1201,"<="&$C15,Data!$J$2:$J$1201,"Cancelled") -> 4 | I15: =COUNTIFS(Data!$B$2:$B$1201,">="&$B15,Data!$B$2:$B$1201,"<="&$C15,Data!$J$2:$J$1201,"RTO") -> 6 | J15: =IFERROR(F15/D15,0) -> 0.73958333 | K15: =IFERROR(G15/D15,0) -> 0.15625
... A17: Week 14 | B17: 46295 | C17: =B17+6 -> 46301 | D17: =COUNTIFS(Data!$B$2:$B$1201,">="&$B17,Data!$B$2:$B$1201,"<="&$C17) -> 9 | E17: =SUMIFS(Data!$H$2:$H$1201,Data!$B$2:$B$1201,">="&$B17,Data!$B$2:$B$1201,"<="&$C17) -> 6428 | F17: =COUNTIFS(Data!$B$2:$B$1201,">="&$B17,Data!$B$2:$B$1201,"<="&$C17,Data!$J$2:$J$1201,"Delivered") -> 7 | G17: =COUNTIFS(Data!$B$2:$B$1201,">="&$B17,Data!$B$2:$B$1201,"<="&$C17,Data!$J$2:$J$1201,"Returned") -> 1 | H17: =COUNTIFS(Data!$B$2:$B$1201,">="&$B17,Data!$B$2:$B$1201,"<="&$C17,Data!$J$2:$J$1201,"Cancelled") -> 1 | I17: =COUNTIFS(Data!$B$2:$B$1201,">="&$B17,Data!$B$2:$B$1201,"<="&$C17,Data!$J$2:$J$1201,"RTO") -> 0 | J17: =IFERROR(F17/D17,0) -> 0.77777778 | K17: =IFERROR(G17/D17,0) -> 0.11111111
A19: Note: data covers 01-Jul-2026 to 30-Sep-2026, so Week 14 is a partial week (2 days).

Sheet Monthly MIS
A1: Monthly MIS Report
A3: Month | B3: Month Start | C3: Month End | D3: Orders | E3: Revenue (INR) | F3: Avg Order Value (INR) | G3: Delivered | H3: Returned | I3: Cancelled | J3: RTO | K3: Delivery % | L3: Return % | M3: COD Share %
A4: July 2026 | B4: 46204 | C4: =EOMONTH(B4,0) -> 46234 | D4: =COUNTIFS(Data!$B$2:$B$1201,">="&$B4,Data!$B$2:$B$1201,"<="&$C4) -> 363 | E4: =SUMIFS(Data!$H$2:$H$1201,Data!$B$2:$B$1201,">="&$B4,Data!$B$2:$B$1201,"<="&$C4) -> 292522 | F4: =IFERROR(E4/D4,0) -> 805.84573 | G4: =COUNTIFS(Data!$B$2:$B$1201,">="&$B4,Data!$B$2:$B$1201,"<="&$C4,Data!$J$2:$J$1201,"Delivered") -> 300 | H4: =COUNTIFS(Data!$B$2:$B$1201,">="&$B4,Data!$B$2:$B$1201,"<="&$C4,Data!$J$2:$J$1201,"Returned") -> 27 | I4: =COUNTIFS(Data!$B$2:$B$1201,">="&$B4,Data!$B$2:$B$1201,"<="&$C4,Data!$J$2:$J$1201,"Cancelled") -> 11 | J4: =COUNTIFS(Data!$B$2:$B$1201,">="&$B4,Data!$B$2:$B$1201,"<="&$C4,Data!$J$2:$J$1201,"RTO") -> 25 | K4: =IFERROR(G4/D4,0) -> 0.82644628 | L4: =IFERROR(H4/D4,0) -> 0.074380165 | M4: =IFERROR(COUNTIFS(Data!$B$2:$B$1201,">="&$B4,Data!$B$2:$B$1201,"<="&$C4,Data!$I$2:$I$1201,"COD")/D4,0) -> 0.37190083
A5: August 2026 | B5: 46235 | C5: =EOMONTH(B5,0) -> 46265 | D5: =COUNTIFS(Data!$B$2:$B$1201,">="&$B5,Data!$B$2:$B$1201,"<="&$C5) -> 421 | E5: =SUMIFS(Data!$H$2:$H$1201,Data!$B$2:$B$1201,">="&$B5,Data!$B$2:$B$1201,"<="&$C5) -> 342860 | F5: =IFERROR(E5/D5,0) -> 814.3943 | G5: =COUNTIFS(Data!$B$2:$B$1201,">="&$B5,Data!$B$2:$B$1201,"<="&$C5,Data!$J$2:$J$1201,"Delivered") -> 351 | H5: =COUNTIFS(Data!$B$2:$B$1201,">="&$B5,Data!$B$2:$B$1201,"<="&$C5,Data!$J$2:$J$1201,"Returned") -> 28 | I5: =COUNTIFS(Data!$B$2:$B$1201,">="&$B5,Data!$B$2:$B$1201,"<="&$C5,Data!$J$2:$J$1201,"Cancelled") -> 16 | J5: =COUNTIFS(Data!$B$2:$B$1201,">="&$B5,Data!$B$2:$B$1201,"<="&$C5,Data!$J$2:$J$1201,"RTO") -> 26 | K5: =IFERROR(G5/D5,0) -> 0.83372922 | L5: =IFERROR(H5/D5,0) -> 0.066508314 | M5: =IFERROR(COUNTIFS(Data!$B$2:$B$1201,">="&$B5,Data!$B$2:$B$1201,"<="&$C5,Data!$I$2:$I$1201,"COD")/D5,0) -> 0.37529691
A6: September 2026 | B6: 46266 | C6: =EOMONTH(B6,0) -> 46295 | D6: =COUNTIFS(Data!$B$2:$B$1201,">="&$B6,Data!$B$2:$B$1201,"<="&$C6) -> 416 | E6: =SUMIFS(Data!$H$2:$H$1201,Data!$B$2:$B$1201,">="&$B6,Data!$B$2:$B$1201,"<="&$C6) -> 347334 | F6: =IFERROR(E6/D6,0) -> 834.9375 | G6: =COUNTIFS(Data!$B$2:$B$1201,">="&$B6,Data!$B$2:$B$1201,"<="&$C6,Data!$J$2:$J$1201,"Delivered") -> 335 | H6: =COUNTIFS(Data!$B$2:$B$1201,">="&$B6,Data!$B$2:$B$1201,"<="&$C6,Data!$J$2:$J$1201,"Returned") -> 34 | I6: =COUNTIFS(Data!$B$2:$B$1201,">="&$B6,Data!$B$2:$B$1201,"<="&$C6,Data!$J$2:$J$1201,"Cancelled") -> 21 | J6: =COUNTIFS(Data!$B$2:$B$1201,">="&$B6,Data!$B$2:$B$1201,"<="&$C6,Data!$J$2:$J$1201,"RTO") -> 26 | K6: =IFERROR(G6/D6,0) -> 0.80528846 | L6: =IFERROR(H6/D6,0) -> 0.081730769 | M6: =IFERROR(COUNTIFS(Data!$B$2:$B$1201,">="&$B6,Data!$B$2:$B$1201,"<="&$C6,Data!$I$2:$I$1201,"COD")/D6,0) -> 0.40865385

Sheet Data
A1: Order ID | B1: Order Date | C1: City | D1: Category | E1: Product | F1: Qty | G1: Unit Price (INR) | H1: Order Value (INR) | I1: Payment Mode | J1: Order Status | K1: Delivery Days
A2: ORD10001 | B2: 46204 | C2: Kolkata | D2: Haircare | E2: Shampoo | F2: 1 | G2: 568 | H2: =F2*G2 -> 568 | I2: Prepaid | J2: Delivered | K2: 4
A3: ORD10002 | B3: 46204 | C3: Kolkata | D3: Bath & Body | E3: Hand Cream | F3: 1 | G3: 308 | H3: =F3*G3 -> 308 | I3: Prepaid | J3: Delivered | K3: 5
A4: ORD10003 | B4: 46204 | C4: Hyderabad | D4: Wellness | E4: Essential Oil | F4: 1 | G4: 1078 | H4: =F4*G4 -> 1078 | I4: Prepaid | J4: Delivered | K4: 3
A5: ORD10004 | B5: 46204 | C5: Jaipur | D5: Skincare | E5: Moisturiser | F5: 1 | G5: 708 | H5: =F5*G5 -> 708 | I5: COD | J5: Returned | K5: 3
A6: ORD10005 | B6: 46204 | C6: Delhi | D6: Skincare | E6: Moisturiser | F6: 1 | G6: 678 | H6: =F6*G6 -> 678 | I6: COD | J6: Delivered | K6: 4
A7: ORD10006 | B7: 46204 | C7: Mumbai | D7: Wellness | E7: Vitamin Gummies | F7: 1 | G7: 1008 | H7: =F7*G7 -> 1008 | I7: COD | J7: Delivered | K7: 4
A8: ORD10007 | B8: 46204 | C8: Hyderabad | D8: Makeup | E8: Compact Powder | F8: 3 | G8: 808 | H8: =F8*G8 -> 2424 | I8: COD | J8: Delivered | K8: 3
A9: ORD10008 | B9: 46204 | C9: Lucknow | D9: Makeup | E9: Lip Balm | F9: 1 | G9: 818 | H9: =F9*G9 -> 818 | I9: Prepaid | J9: Delivered | K9: 4
A10: ORD10009 | B10: 46205 | C10: Kolkata | D10: Wellness | E10: Vitamin Gummies | F10: 1 | G10: 1148 | H10: =F10*G10 -> 1148 | I10: Prepaid | J10: Delivered | K10: 6
A11: ORD10010 | B11: 46205 | C11: Delhi | D11: Bath & Body | E11: Hand Cream | F11: 2 | G11: 368 | H11: =F11*G11 -> 736 | I11: Prepaid | J11: Delivered | K11: 5
A12: ORD10011 | B12: 46205 | C12: Bengaluru | D12: Skincare | E12: Face Serum | F12: 1 | G12: 628 | H12: =F12*G12 -> 628 | I12: COD | J12: RTO
A13: ORD10012 | B13: 46205 | C13: Kolkata | D13: Makeup | E13: Lip Balm | F13: 1 | G13: 828 | H13: =F13*G13 -> 828 | I13: Prepaid | J13: Delivered | K13: 4
A14: ORD10013 | B14: 46205 | C14: Mumbai | D14: Skincare | E14: Sunscreen SPF50 | F14: 3 | G14: 548 | H14: =F14*G14 -> 1644 | I14: Prepaid | J14: Cancelled
A15: ORD10014 | B15: 46205 | C15: Jaipur | D15: Skincare | E15: Face Serum | F15: 2 | G15: 708 | H15: =F15*G15 -> 1416 | I15: COD | J15: Delivered | K15: 3
A16: ORD10015 | B16: 46205 | C16: Kolkata | D16: Makeup | E16: Compact Powder | F16: 1 | G16: 358 | H16: =F16*G16 -> 358 | I16: COD | J16: Delivered | K16: 4
A17: ORD10016 | B17: 46205 | C17: Bengaluru | D17: Makeup | E17: Kajal | F17: 1 | G17: 818 | H17: =F17*G17 -> 818 | I17: Prepaid | J17: Returned | K17: 5
A18: ORD10017 | B18: 46206 | C18: Hyderabad | D18: Bath & Body | E18: Hand Cream | F18: 1 | G18: 588 | H18: =F18*G18 -> 588 | I18: COD | J18: RTO
A19: ORD10018 | B19: 46206 | C19: Bengaluru | D19: Skincare | E19: Sunscreen SPF50 | F19: 2 | G19: 598 | H19: =F19*G19 -> 1196 | I19: Prepaid | J19: Delivered | K19: 4
A20: ORD10019 | B20: 46206 | C20: Hyderabad | D20: Haircare | E20: Hair Mask | F20: 1 | G20: 338 | H20: =F20*G20 -> 338 | I20: Prepaid | J20: Delivered | K20: 4
A21: ORD10020 | B21: 46206 | C21: Hyderabad | D21: Makeup | E21: Lip Balm | F21: 1 | G21: 598 | H21: =F21*G21 -> 598 | I21: COD | J21: Delivered | K21: 3
A22: ORD10021 | B22: 46206 | C22: Jaipur | D22: Skincare | E22: Face Serum | F22: 1 | G22: 858 | H22: =F22*G22 -> 858 | I22: COD | J22: RTO
A23: ORD10022 | B23: 46206 | C23: Kolkata | D23: Wellness | E23: Herbal Tea | F23: 3 | G23: 798 | H23: =F23*G23 -> 2394 | I23: COD | J23: Delivered | K23: 4
A24: ORD10023 | B24: 46206 | C24: Pune | D24: Bath & Body | E24: Body Lotion | F24: 1 | G24: 218 | H24: =F24*G24 -> 218 | I24: Prepaid | J24: Delivered | K24: 4
A25: ORD10024 | B25: 46206 | C25: Delhi | D25: Wellness | E25: Essential Oil | F25: 1 | G25: 988 | H25: =F25*G25 -> 988 | I25: Prepaid | J25: Delivered | K25: 4
A26: ORD10025 | B26: 46207 | C26: Mumbai | D26: Skincare | E26: Face Serum | F26: 1 | G26: 748 | H26: =F26*G26 -> 748 | I26: Prepaid | J26: Delivered | K26: 4
A27: ORD10026 | B27: 46207 | C27: Mumbai | D27: Makeup | E27: Lip Balm | F27: 2 | G27: 698 | H27: =F27*G27 -> 1396 | I27: Prepaid | J27: Delivered | K27: 4
A28: ORD10027 | B28: 46207 | C28: Delhi | D28: Skincare | E28: Face Wash | F28: 1 | G28: 458 | H28: =F28*G28 -> 458 | I28: Prepaid | J28: Delivered | K28: 2
A29: ORD10028 | B29: 46207 | C29: Jaipur | D29: Skincare | E29: Face Serum | F29: 2 | G29: 588 | H29: =F29*G29 -> 1176 | I29: Prepaid | J29: Delivered | K29: 4
A30: ORD10029 | B30: 46207 | C30: Kolkata | D30: Wellness | E30: Vitamin Gummies | F30: 1 | G30: 1158 | H30: =F30*G30 -> 1158 | I30: Prepaid | J30: Delivered | K30: 5
A31: ORD10030 | B31: 46207 | C31: Jaipur | D31: Skincare | E31: Face Wash | F31: 1 | G31: 428 | H31: =F31*G31 -> 428 | I31: Prepaid | J31: Delivered | K31: 5
A32: ORD10031 | B32: 46207 | C32: Pune | D32: Bath & Body | E32: Body Wash | F32: 1 | G32: 278 | H32: =F32*G32 -> 278 | I32: Prepaid | J32: Delivered | K32: 5
A33: ORD10032 | B33: 46207 | C33: Hyderabad | D33: Makeup | E33: Kajal | F33: 2 | G33: 568 | H33: =F33*G33 -> 1136 | I33: COD | J33: RTO
A34: ORD10033 | B34: 46207 | C34: Jaipur | D34: Skincare | E34: Sunscreen SPF50 | F34: 1 | G34: 548 | H34: =F34*G34 -> 548 | I34: COD | J34: RTO
A35: ORD10034 | B35: 46207 | C35: Hyderabad | D35: Skincare | E35: Face Serum | F35: 1 | G35: 488 | H35: =F35*G35 -> 488 | I35: Prepaid | J35: Delivered | K35: 3
A36: ORD10035 | B36: 46207 | C36: Delhi | D36: Haircare | E36: Shampoo | F36: 1 | G36: 748 | H36: =F36*G36 -> 748 | I36: COD | J36: Delivered | K36: 3
A37: ORD10036 | B37: 46207 | C37: Jaipur | D37: Haircare | E37: Shampoo | F37: 1 | G37: 338 | H37: =F37*G37 -> 338 | I37: Prepaid | J37: Delivered | K37: 4
A38: ORD10037 | B38: 46207 | C38: Delhi | D38: Bath & Body | E38: Body Lotion | F38: 1 | G38: 388 | H38: =F38*G38 -> 388 | I38: Prepaid | J38: Delivered | K38: 3
A39: ORD10038 | B39: 46207 | C39: Pune | D39: Wellness | E39: Vitamin Gummies | F39: 1 | G39: 928 | H39: =F39*G39 -> 928 | I39: COD | J39: Delivered | K39: 3
A40: ORD10039 | B40: 46207 | C40: Jaipur | D40: Bath & Body | E40: Hand Cream | F40: 1 | G40: 338 | H40: =F40*G40 -> 338 | I40: Prepaid | J40: Delivered | K40: 5
...

Sheet About
A1: About this workbook
A3: Purpose: Practice MIS reporting for an E-commerce / D2C business (daily, weekly and monthly reports).
A4: Data: SIMULATED sample data (1,200 orders, 01-Jul-2026 to 30-Sep-2026). Not real company data.
A6: Sheets:
A7: Dashboard - KPI cards and 4 charts; Dashboard Data - tables behind the charts
A8: Daily MIS - one row per day (92 days)
A9: Weekly MIS - 14 weeks
A10: Monthly MIS - Jul, Aug, Sep
A11: Data - raw order data (blue font = input values, black = formulas)
A13: How to use with your own data: paste new rows in the Data sheet (columns A-K) and extend the formula ranges / dates in the MIS sheets.
A14: Definitions: Delivery % = Delivered / Orders; Return % = Returned / Orders; RTO = Return To Origin (courier could not deliver, mostly COD).
A15: Net Delivered Revenue = order value of orders with status Delivered only.
A16: Formulas used: COUNTIFS, SUMIFS, AVERAGE, IFERROR, EOMONTH.
